Workbook

Sheet Match Results
A1: Date | B1: Court | C1: Player1 | D1: Player2 | E1: Score1 | F1: Score2 | G1: Player3 | H1: Player4
A2: 45932 | B2: Power Court | C2: Vivek | D2: Sergio | E2: 3 | F2: 0 | G2: Bassam | H2: Joel
A3: 45932 | B3: Power Court | C3: Ahmad DD | D3: Sergio | E3: 3 | F3: 3 | G3: Vivek | H3: Own
A4: 45932 | B4: Power Court | C4: Ahmad DD | D4: Dana | E4: 2 | F4: 1 | G4: Sergio | H4: Dauren
A5: 45932 | B5: Power Court | C5: Ahmad DD | D5: Bassam | E5: 3 | F5: 0 | G5: Bruno | H5: Dana
A6: 45932 | B6: Power Court | C6: Vivek | D6: Joel | E6: 2 | F6: 1 | G6: Ahmad DD | H6: Own
A7: 45932 | B7: Power Court | C7: Vivek | D7: Dauren | E7: 3 | F7: 1 | G7: Own | H7: Bruno
A8: 45932 | B8: Power Court | C8: Sergio | D8: Natalya | E8: 2 | F8: 1 | G8: Joel | H8: Dana
A9: 45932 | B9: Power Court | C9: Dauren | D9: Dana | E9: 2 | F9: 1 | G9: Bruno | H9: Natalya
A10: 45932 | B10: Power Court | C10: Natalya | D10: Vivek | E10: 2 | F10: 1 | G10: Own | H10: Joel
A11: 45932 | B11: Power Court | C11: Natalya | D11: Bassam | E11: 1 | F11: 2 | G11: Vivek | H11: Joel
A12: 45932 | B12: Rising Court | C12: Bassam | D12: Dana | E12: 2 | F12: 1 | G12: Sergio | H12: Natalya
A13: 45932 | B13: Rising Court
A14: 45932 | B14: Rising Court
A15: 45932 | B15: Rising Court
A16: 45932 | B16: Rising Court
A17: 45932 | B17: Rising Court
A18: 45932 | B18: Rising Court
A19: 45932 | B19: Rising Court
A20: 45932 | B20: Rising Court
A21: 45932 | B21: Rising Court
A22: =A13+7 -> 45939 | B22: Power Court | C22: Tin | D22: Bruno | E22: 1 | F22: 2 | G22: Joel | H22: Hazem
A23: =A22 -> 45939 | B23: Power Court | C23: Tin | D23: Renato | E23: 2 | F23: 1 | G23: Andreas | H23: Julio
A24: =A23 -> 45939 | B24: Power Court | C24: Dana | D24: Dauren | E24: 2 | F24: 1 | G24: Bruno | H24: Natalya
A25: =A24 -> 45939 | B25: Power Court | C25: Joel | D25: Ahmad DD | E25: 3 | F25: 0 | G25: Renato | H25: Hazem
A26: =A25 -> 45939 | B26: Power Court | C26: Bruno | D26: Andreas | E26: 2 | F26: 1 | G26: Tin | H26: Dauren
A27: =A26 -> 45939 | B27: Power Court | C27: Joel | D27: Dana | E27: 1 | F27: 2 | G27: Ahmad DD | H27: Natalya
A28: =A27 -> 45939 | B28: Power Court | C28: Hazem | D28: Tin | E28: 2 | F28: 1 | G28: Andreas | H28: Julio
A29: =A28 -> 45939 | B29: Power Court | C29: Renato | D29: Joel | E29: 3 | F29: 0 | G29: Tin | H29: Hazem
A30: =A29 -> 45939 | B30: Power Court | C30: Ahmad DD | D30: Bruno | E30: 2 | F30: 1 | G30: Andreas | H30: Dauren
A31: =A30 -> 45939 | B31: Power Court | C31: Bruno | D31: Dauren | E31: 2 | F31: 1 | G31: Own | H31: Baobaid
A32: =A31 -> 45939 | B32: Rising Court | C32: Dana | D32: Joel | E32: 2 | F32: 1 | G32: Own | H32: Natalya
A33: =A32 -> 45939 | B33: Rising Court | C33: Andreas | D33: Tin | E33: 2 | F33: 1 | G33: Renato | H33: Joel
A34: =A33 -> 45939 | B34: Rising Court | C34: Bruno | D34: Own | E34: 0 | F34: 2 | G34: Ahmad DD | H34: Baobaid
... A36: =A35 -> 45939 | B36: Rising Court | C36: Hazem | D36: Natalya | E36: 2 | F36: 1 | G36: Dauren | H36: Dana
A37: =A22 -> 45939 | B37: Rising Court | C37: Own | D37: Andreas | E37: 1 | F37: 2 | G37: Julio | H37: Baobaid
A38: =A22 -> 45939 | B38: Rising Court | C38: Ahmad DD | D38: Andreas | E38: 3 | F38: 3 | G38: Baobaid | H38: Julio
A39: =A22 -> 45939 | B39: Rising Court
A40: =A22 -> 45939 | B40: Rising Court
A41: =A22 -> 45939 | B41: Rising Court
...

Sheet Helper Results
A1: Date | B1: Court | C1: MatchID | D1: Player | E1: Result | F1: Points
A2: ='Match Results'!A2 -> 45932 | B2: ='Match Results'!B2 -> Power Court | C2: 1 | D2: ='Match Results'!C2 -> Vivek | E2: =IF('Match Results'!E2>'Match Results'!F2,"Win",IF('Match Results'!E2='Match Results'!F2,"Draw","Loss")) -> Win | F2: =IF(E2="Win",3,IF(E2="Draw",2,1)) -> 3
A3: ='Match Results'!A2 -> 45932 | B3: ='Match Results'!B3 -> Power Court | C3: 1 | D3: ='Match Results'!D2 -> Sergio | E3: =IF('Match Results'!E2>'Match Results'!F2,"Win",IF('Match Results'!E2='Match Results'!F2,"Draw","Loss")) -> Win | F3: =IF(E3="Win",3,IF(E3="Draw",2,1)) -> 3
A4: ='Match Results'!A2 -> 45932 | B4: ='Match Results'!B4 -> Power Court | C4: 1 | D4: ='Match Results'!G2 -> Bassam | E4: =IF('Match Results'!F2>'Match Results'!E2,"Win",IF('Match Results'!E2='Match Results'!F2,"Draw","Loss")) -> Loss | F4: =IF(E4="Win",3,IF(E4="Draw",2,1)) -> 1
A5: ='Match Results'!A2 -> 45932 | B5: ='Match Results'!B5 -> Power Court | C5: 1 | D5: ='Match Results'!H2 -> Joel | E5: =IF('Match Results'!F2>'Match Results'!E2,"Win",IF('Match Results'!E2='Match Results'!F2,"Draw","Loss")) -> Loss | F5: =IF(E5="Win",3,IF(E5="Draw",2,1)) -> 1
A6: ='Match Results'!A3 -> 45932 | B6: ='Match Results'!B6 -> Power Court | C6: 2 | D6: ='Match Results'!C3 -> Ahmad DD | E6: =IF('Match Results'!E3>'Match Results'!F3,"Win",IF('Match Results'!E3='Match Results'!F3,"Draw","Loss")) -> Draw | F6: =IF(E6="Win",3,IF(E6="Draw",2,1)) -> 2
A7: ='Match Results'!A3 -> 45932 | B7: ='Match Results'!B7 -> Power Court | C7: 2 | D7: ='Match Results'!D3 -> Sergio | E7: =IF('Match Results'!E3>'Match Results'!F3,"Win",IF('Match Results'!E3='Match Results'!F3,"Draw","Loss")) -> Draw | F7: =IF(E7="Win",3,IF(E7="Draw",2,1)) -> 2
A8: ='Match Results'!A3 -> 45932 | B8: ='Match Results'!B8 -> Power Court | C8: 2 | D8: ='Match Results'!G3 -> Vivek | E8: =IF('Match Results'!F3>'Match Results'!E3,"Win",IF('Match Results'!E3='Match Results'!F3,"Draw","Loss")) -> Draw | F8: =IF(E8="Win",3,IF(E8="Draw",2,1)) -> 2
A9: ='Match Results'!A3 -> 45932 | B9: ='Match Results'!B9 -> Power Court | C9: 2 | D9: ='Match Results'!H3 -> Own | E9: =IF('Match Results'!F3>'Match Results'!E3,"Win",IF('Match Results'!E3='Match Results'!F3,"Draw","Loss")) -> Draw | F9: =IF(E9="Win",3,IF(E9="Draw",2,1)) -> 2
A10: ='Match Results'!A4 -> 45932 | B10: ='Match Results'!B10 -> Power Court | C10: 3 | D10: ='Match Results'!C4 -> Ahmad DD | E10: =IF('Match Results'!E4>'Match Results'!F4,"Win",IF('Match Results'!E4='Match Results'!F4,"Draw","Loss")) -> Win | F10: =IF(E10="Win",3,IF(E10="Draw",2,1)) -> 3
A11: ='Match Results'!A4 -> 45932 | B11: ='Match Results'!B11 -> Power Court | C11: 3 | D11: ='Match Results'!D4 -> Dana | E11: =IF('Match Results'!E4>'Match Results'!F4,"Win",IF('Match Results'!E4='Match Results'!F4,"Draw","Loss")) -> Win | F11: =IF(E11="Win",3,IF(E11="Draw",2,1)) -> 3
A12: ='Match Results'!A4 -> 45932 | B12: ='Match Results'!B12 -> Rising Court | C12: 3 | D12: ='Match Results'!G4 -> Sergio | E12: =IF('Match Results'!F4>'Match Results'!E4,"Win",IF('Match Results'!E4='Match Results'!F4,"Draw","Loss")) -> Loss | F12: =IF(E12="Win",3,IF(E12="Draw",2,1)) -> 1
A13: ='Match Results'!A4 -> 45932 | B13: ='Match Results'!B13 -> Rising Court | C13: 3 | D13: ='Match Results'!H4 -> Dauren | E13: =IF('Match Results'!F4>'Match Results'!E4,"Win",IF('Match Results'!E4='Match Results'!F4,"Draw","Loss")) -> Loss | F13: =IF(E13="Win",3,IF(E13="Draw",2,1)) -> 1
A14: ='Match Results'!A5 -> 45932 | B14: ='Match Results'!B14 -> Rising Court | C14: 4 | D14: ='Match Results'!C5 -> Ahmad DD | E14: =IF('Match Results'!E5>'Match Results'!F5,"Win",IF('Match Results'!E5='Match Results'!F5,"Draw","Loss")) -> Win | F14: =IF(E14="Win",3,IF(E14="Draw",2,1)) -> 3
A15: ='Match Results'!A5 -> 45932 | B15: ='Match Results'!B15 -> Rising Court | C15: 4 | D15: ='Match Results'!D5 -> Bassam | E15: =IF('Match Results'!E5>'Match Results'!F5,"Win",IF('Match Results'!E5='Match Results'!F5,"Draw","Loss")) -> Win | F15: =IF(E15="Win",3,IF(E15="Draw",2,1)) -> 3
A16: ='Match Results'!A5 -> 45932 | B16: ='Match Results'!B16 -> Rising Court | C16: 4 | D16: ='Match Results'!G5 -> Bruno | E16: =IF('Match Results'!F5>'Match Results'!E5,"Win",IF('Match Results'!E5='Match Results'!F5,"Draw","Loss")) -> Loss | F16: =IF(E16="Win",3,IF(E16="Draw",2,1)) -> 1
A17: ='Match Results'!A5 -> 45932 | B17: ='Match Results'!B17 -> Rising Court | C17: 4 | D17: ='Match Results'!H5 -> Dana | E17: =IF('Match Results'!F5>'Match Results'!E5,"Win",IF('Match Results'!E5='Match Results'!F5,"Draw","Loss")) -> Loss | F17: =IF(E17="Win",3,IF(E17="Draw",2,1)) -> 1
A18: ='Match Results'!A6 -> 45932 | B18: ='Match Results'!B18 -> Rising Court | C18: 5 | D18: ='Match Results'!C6 -> Vivek | E18: =IF('Match Results'!E6>'Match Results'!F6,"Win",IF('Match Results'!E6='Match Results'!F6,"Draw","Loss")) -> Win | F18: =IF(E18="Win",3,IF(E18="Draw",2,1)) -> 3
A19: ='Match Results'!A6 -> 45932 | B19: ='Match Results'!B19 -> Rising Court | C19: 5 | D19: ='Match Results'!D6 -> Joel | E19: =IF('Match Results'!E6>'Match Results'!F6,"Win",IF('Match Results'!E6='Match Results'!F6,"Draw","Loss")) -> Win | F19: =IF(E19="Win",3,IF(E19="Draw",2,1)) -> 3
A20: ='Match Results'!A6 -> 45932 | B20: ='Match Results'!B20 -> Rising Court | C20: 5 | D20: ='Match Results'!G6 -> Ahmad DD | E20: =IF('Match Results'!F6>'Match Results'!E6,"Win",IF('Match Results'!E6='Match Results'!F6,"Draw","Loss")) -> Loss | F20: =IF(E20="Win",3,IF(E20="Draw",2,1)) -> 1
A21: ='Match Results'!A6 -> 45932 | B21: ='Match Results'!B21 -> Rising Court | C21: 5 | D21: ='Match Results'!H6 -> Own | E21: =IF('Match Results'!E12>'Match Results'!F12,"Win",IF('Match Results'!E12='Match Results'!F12,"Draw","Loss")) -> Win | F21: =IF(E21="Win",3,IF(E21="Draw",2,1)) -> 3
A22: ='Match Results'!A6 -> 45932 | B22: ='Match Results'!B22 -> Power Court | C22: 6 | D22: ='Match Results'!C7 -> Vivek | E22: =IF('Match Results'!E7>'Match Results'!F7,"Win",IF('Match Results'!E7='Match Results'!F8,"Draw","Loss")) -> Win | F22: =IF(E22="Win",3,IF(E22="Draw",2,1)) -> 3
A23: ='Match Results'!A6 -> 45932 | B23: ='Match Results'!B23 -> Power Court | C23: 6 | D23: ='Match Results'!D7 -> Dauren | E23: =IF('Match Results'!E7>'Match Results'!F7,"Win",IF('Match Results'!E7='Match Results'!F8,"Draw","Loss")) -> Win | F23: =IF(E23="Win",3,IF(E23="Draw",2,1)) -> 3
A24: ='Match Results'!A6 -> 45932 | B24: ='Match Results'!B24 -> Power Court | C24: 6 | D24: ='Match Results'!G7 -> Own | E24: =IF('Match Results'!E7>'Match Results'!F7,"Win",IF('Match Results'!E7='Match Results'!F8,"Draw","Loss")) -> Win | F24: =IF(E24="Win",3,IF(E24="Draw",2,1)) -> 3
A25: ='Match Results'!A6 -> 45932 | B25: ='Match Results'!B25 -> Power Court | C25: 6 | D25: ='Match Results'!H7 -> Bruno | E25: =IF('Match Results'!E7>'Match Results'!F7,"Win",IF('Match Results'!E7='Match Results'!F8,"Draw","Loss")) -> Win | F25: =IF(E25="Win",3,IF(E25="Draw",2,1)) -> 3
A26: ='Match Results'!A8 -> 45932 | B26: ='Match Results'!B26 -> Power Court | C26: 7 | D26: ='Match Results'!C8 -> Sergio | E26: =IF('Match Results'!E8>'Match Results'!F8,"Win",IF('Match Results'!E8='Match Results'!F8,"Draw","Loss")) -> Win | F26: =IF(E26="Win",3,IF(E26="Draw",2,1)) -> 3
A27: ='Match Results'!A8 -> 45932 | B27: ='Match Results'!B27 -> Power Court | C27: 7 | D27: ='Match Results'!D8 -> Natalya | E27: =IF('Match Results'!E8>'Match Results'!F8,"Win",IF('Match Results'!E8='Match Results'!F8,"Draw","Loss")) -> Win | F27: =IF(E27="Win",3,IF(E27="Draw",2,1)) -> 3
A28: ='Match Results'!A8 -> 45932 | B28: ='Match Results'!B28 -> Power Court | C28: 7 | D28: ='Match Results'!G8 -> Joel | E28: =IF('Match Results'!F8>'Match Results'!E8,"Win",IF('Match Results'!E8='Match Results'!F8,"Draw","Loss")) -> Loss | F28: =IF(E28="Win",3,IF(E28="Draw",2,1)) -> 1
A29: ='Match Results'!A8 -> 45932 | B29: ='Match Results'!B29 -> Power Court | C29: 7 | D29: ='Match Results'!H8 -> Dana | E29: =IF('Match Results'!F8>'Match Results'!E8,"Win",IF('Match Results'!E8='Match Results'!F8,"Draw","Loss")) -> Loss | F29: =IF(E29="Win",3,IF(E29="Draw",2,1)) -> 1
A30: ='Match Results'!A9 -> 45932 | B30: ='Match Results'!B30 -> Power Court | C30: 8 | D30: ='Match Results'!C9 -> Dauren | E30: =IF('Match Results'!E9>'Match Results'!F9,"Win",IF('Match Results'!E9='Match Results'!F9,"Draw","Loss")) -> Win | F30: =IF(E30="Win",3,IF(E30="Draw",2,1)) -> 3
A31: ='Match Results'!A9 -> 45932 | B31: ='Match Results'!B31 -> Power Court | C31: 8 | D31: ='Match Results'!D9 -> Dana | E31: =IF('Match Results'!E9>'Match Results'!F9,"Win",IF('Match Results'!E9='Match Results'!F9,"Draw","Loss")) -> Win | F31: =IF(E31="Win",3,IF(E31="Draw",2,1)) -> 3
A32: ='Match Results'!A9 -> 45932 | B32: ='Match Results'!B32 -> Rising Court | C32: 8 | D32: ='Match Results'!G9 -> Bruno | E32: =IF('Match Results'!F9>'Match Results'!E9,"Win",IF('Match Results'!E9='Match Results'!F9,"Draw","Loss")) -> Loss | F32: =IF(E32="Win",3,IF(E32="Draw",2,1)) -> 1
A33: ='Match Results'!A9 -> 45932 | B33: ='Match Results'!B33 -> Rising Court | C33: 8 | D33: ='Match Results'!H9 -> Natalya | E33: =IF('Match Results'!F9>'Match Results'!E9,"Win",IF('Match Results'!E9='Match Results'!F9,"Draw","Loss")) -> Loss | F33: =IF(E33="Win",3,IF(E33="Draw",2,1)) -> 1
A34: ='Match Results'!A10 -> 45932 | B34: ='Match Results'!B34 -> Rising Court | C34: 9 | D34: ='Match Results'!C10 -> Natalya | E34: =IF('Match Results'!E10>'Match Results'!F10,"Win",IF('Match Results'!E10='Match Results'!F10,"Draw","Loss")) -> Win | F34: =IF(E34="Win",3,IF(E34="Draw",2,1)) -> 3
A35: ='Match Results'!A10 -> 45932 | B35: ='Match Results'!B35 -> Rising Court | C35: 9 | D35: ='Match Results'!D10 -> Vivek | E35: =IF('Match Results'!E10>'Match Results'!F10,"Win",IF('Match Results'!E10='Match Results'!F10,"Draw","Loss")) -> Win | F35: =IF(E35="Win",3,IF(E35="Draw",2,1)) -> 3
A36: ='Match Results'!A10 -> 45932 | B36: ='Match Results'!B36 -> Rising Court | C36: 9 | D36: ='Match Results'!G10 -> Own | E36: =IF('Match Results'!F10>'Match Results'!E10,"Win",IF('Match Results'!E10='Match Results'!F10,"Draw","Loss")) -> Loss | F36: =IF(E36="Win",3,IF(E36="Draw",2,1)) -> 1
A37: ='Match Results'!A10 -> 45932 | B37: ='Match Results'!B37 -> Rising Court | C37: 9 | D37: ='Match Results'!H10 -> Joel | E37: =IF('Match Results'!F10>'Match Results'!E10,"Win",IF('Match Results'!E10='Match Results'!F10,"Draw","Loss")) -> Loss | F37: =IF(E37="Win",3,IF(E37="Draw",2,1)) -> 1
A38: ='Match Results'!A11 -> 45932 | B38: ='Match Results'!B38 -> Rising Court | C38: 10 | D38: ='Match Results'!C11 -> Natalya | E38: =IF('Match Results'!E11>'Match Results'!F11,"Win",IF('Match Results'!E11='Match Results'!F11,"Draw","Loss")) -> Loss | F38: =IF(E38="Win",3,IF(E38="Draw",2,1)) -> 1
A39: ='Match Results'!A11 -> 45932 | B39: ='Match Results'!B39 -> Rising Court | C39: 10 | D39: ='Match Results'!D11 -> Bassam | E39: =IF('Match Results'!E11>'Match Results'!F11,"Win",IF('Match Results'!E11='Match Results'!F11,"Draw","Loss")) -> Loss | F39: =IF(E39="Win",3,IF(E39="Draw",2,1)) -> 1
A40: ='Match Results'!A11 -> 45932 | B40: ='Match Results'!B40 -> Rising Court | C40: 10 | D40: ='Match Results'!G11 -> Vivek | E40: =IF('Match Results'!F11>'Match Results'!E11,"Win",IF('Match Results'!E11='Match Results'!F11,"Draw","Loss")) -> Win | F40: =IF(E40="Win",3,IF(E40="Draw",2,1)) -> 3
...

Sheet Leaderboard
A1: # | B1: Player | C1: Total Games | D1: Wins | E1: Draws | F1: Losses | G1: Base Points | H1: Bonus Points | I1: Total Points | J1: Rank
A2: 1 | B2: Joel | C2: =COUNTIF('Helper Results'!D:D,B2) -> 25 | D2: =COUNTIFS('Helper Results'!D:D,B2,'Helper Results'!E:E,"Win") -> 14 | E2: =COUNTIFS('Helper Results'!D:D,B2,'Helper Results'!E:E,"Draw") -> 0 | F2: =COUNTIFS('Helper Results'!D:D,B2,'Helper Results'!E:E,"Loss") -> 11 | G2: =SUMIF('Helper Results'!D:D,B2,'Helper Results'!F:F) -> 53 | H2: {=_xlfn.LET(_xlpm.dates,IFERROR(_xlfn.UNIQUE(_xlfn._xlws.FILTER('Helper Results'!A:A,('Helper Results'!D:D=$B2)*('Helper Results'!A:A<>""))), ""),_xlpm.counts,IF(_xlpm.dates="", 0, COUNTIFS('Helper Results'!D:D, $B2, 'Helper Results'!A:A, _xlpm.dates, 'Helper Results'!E:E, "Win")),SUMPRODUCT(--(_xlpm.counts=3))+2*SUMPRODUCT(--(_xlpm.counts>=4)))} -> 4 | I2: =G2+H2 -> 57 | J2: =RANK(I2,$I$2:$I$31) -> 1
A3: 2 | B3: Ahmad DD | C3: =COUNTIF('Helper Results'!D:D,B3) -> 18 | D3: =COUNTIFS('Helper Results'!D:D,B3,'Helper Results'!E:E,"Win") -> 12 | E3: =COUNTIFS('Helper Results'!D:D,B3,'Helper Results'!E:E,"Draw") -> 2 | F3: =COUNTIFS('Helper Results'!D:D,B3,'Helper Results'!E:E,"Loss") -> 4 | G3: =SUMIF('Helper Results'!D:D,B3,'Helper Results'!F:F) -> 44 | H3: {=_xlfn.LET(_xlpm.dates,IFERROR(_xlfn.UNIQUE(_xlfn._xlws.FILTER('Helper Results'!A:A,('Helper Results'!D:D=$B3)*('Helper Results'!A:A<>""))), ""),_xlpm.counts,IF(_xlpm.dates="", 0, COUNTIFS('Helper Results'!D:D, $B3, 'Helper Results'!A:A, _xlpm.dates, 'Helper Results'!E:E, "Win")),SUMPRODUCT(--(_xlpm.counts=3))+2*SUMPRODUCT(--(_xlpm.counts>=4)))} -> 4 | I3: =G3+H3 -> 48 | J3: =RANK(I3,$I$2:$I$31) -> 2
A4: 3 | B4: Bruno | C4: =COUNTIF('Helper Results'!D:D,B4) -> 20 | D4: =COUNTIFS('Helper Results'!D:D,B4,'Helper Results'!E:E,"Win") -> 10 | E4: =COUNTIFS('Helper Results'!D:D,B4,'Helper Results'!E:E,"Draw") -> 0 | F4: =COUNTIFS('Helper Results'!D:D,B4,'Helper Results'!E:E,"Loss") -> 10 | G4: =SUMIF('Helper Results'!D:D,B4,'Helper Results'!F:F) -> 40 | H4: {=_xlfn.LET(_xlpm.dates,IFERROR(_xlfn.UNIQUE(_xlfn._xlws.FILTER('Helper Results'!A:A,('Helper Results'!D:D=$B4)*('Helper Results'!A:A<>""))), ""),_xlpm.counts,IF(_xlpm.dates="", 0, COUNTIFS('Helper Results'!D:D, $B4, 'Helper Results'!A:A, _xlpm.dates, 'Helper Results'!E:E, "Win")),SUMPRODUCT(--(_xlpm.counts=3))+2*SUMPRODUCT(--(_xlpm.counts>=4)))} -> 2 | I4: =G4+H4 -> 42 | J4: =RANK(I4,$I$2:$I$31) -> 3
A5: 4 | B5: Andreas | C5: =COUNTIF('Helper Results'!D:D,B5) -> 18 | D5: =COUNTIFS('Helper Results'!D:D,B5,'Helper Results'!E:E,"Win") -> 9 | E5: =COUNTIFS('Helper Results'!D:D,B5,'Helper Results'!E:E,"Draw") -> 1 | F5: =COUNTIFS('Helper Results'!D:D,B5,'Helper Results'!E:E,"Loss") -> 8 | G5: =SUMIF('Helper Results'!D:D,B5,'Helper Results'!F:F) -> 37 | H5: {=_xlfn.LET(_xlpm.dates,IFERROR(_xlfn.UNIQUE(_xlfn._xlws.FILTER('Helper Results'!A:A,('Helper Results'!D:D=$B5)*('Helper Results'!A:A<>""))), ""),_xlpm.counts,IF(_xlpm.dates="", 0, COUNTIFS('Helper Results'!D:D, $B5, 'Helper Results'!A:A, _xlpm.dates, 'Helper Results'!E:E, "Win")),SUMPRODUCT(--(_xlpm.counts=3))+2*SUMPRODUCT(--(_xlpm.counts>=4)))} -> 3 | I5: =G5+H5 -> 40 | J5: =RANK(I5,$I$2:$I$31) -> 4
A6: 5 | B6: Renato | C6: =COUNTIF('Helper Results'!D:D,B6) -> 14 | D6: =COUNTIFS('Helper Results'!D:D,B6,'Helper Results'!E:E,"Win") -> 9 | E6: =COUNTIFS('Helper Results'!D:D,B6,'Helper Results'!E:E,"Draw") -> 0 | F6: =COUNTIFS('Helper Results'!D:D,B6,'Helper Results'!E:E,"Loss") -> 5 | G6: =SUMIF('Helper Results'!D:D,B6,'Helper Results'!F:F) -> 32 | H6: {=_xlfn.LET(_xlpm.dates,IFERROR(_xlfn.UNIQUE(_xlfn._xlws.FILTER('Helper Results'!A:A,('Helper Results'!D:D=$B6)*('Helper Results'!A:A<>""))), ""),_xlpm.counts,IF(_xlpm.dates="", 0, COUNTIFS('Helper Results'!D:D, $B6, 'Helper Results'!A:A, _xlpm.dates, 'Helper Results'!E:E, "Win")),SUMPRODUCT(--(_xlpm.counts=3))+2*SUMPRODUCT(--(_xlpm.counts>=4)))} -> 1 | I6: =G6+H6 -> 33 | J6: =RANK(I6,$I$2:$I$31) -> 5
A7: 6 | B7: Dana | C7: =COUNTIF('Helper Results'!D:D,B7) -> 13 | D7: =COUNTIFS('Helper Results'!D:D,B7,'Helper Results'!E:E,"Win") -> 8 | E7: =COUNTIFS('Helper Results'!D:D,B7,'Helper Results'!E:E,"Draw") -> 0 | F7: =COUNTIFS('Helper Results'!D:D,B7,'Helper Results'!E:E,"Loss") -> 5 | G7: =SUMIF('Helper Results'!D:D,B7,'Helper Results'!F:F) -> 29 | H7: {=_xlfn.LET(_xlpm.dates,IFERROR(_xlfn.UNIQUE(_xlfn._xlws.FILTER('Helper Results'!A:A,('Helper Results'!D:D=$B7)*('Helper Results'!A:A<>""))), ""),_xlpm.counts,IF(_xlpm.dates="", 0, COUNTIFS('Helper Results'!D:D, $B7, 'Helper Results'!A:A, _xlpm.dates, 'Helper Results'!E:E, "Win")),SUMPRODUCT(--(_xlpm.counts=3))+2*SUMPRODUCT(--(_xlpm.counts>=4)))} -> 2 | I7: =G7+H7 -> 31 | J7: =RANK(I7,$I$2:$I$31) -> 6
A8: 7 | B8: Caner | C8: =COUNTIF('Helper Results'!D:D,B8) -> 13 | D8: =COUNTIFS('Helper Results'!D:D,B8,'Helper Results'!E:E,"Win") -> 8 | E8: =COUNTIFS('Helper Results'!D:D,B8,'Helper Results'!E:E,"Draw") -> 0 | F8: =COUNTIFS('Helper Results'!D:D,B8,'Helper Results'!E:E,"Loss") -> 5 | G8: =SUMIF('Helper Results'!D:D,B8,'Helper Results'!F:F) -> 29 | H8: {=_xlfn.LET(_xlpm.dates,IFERROR(_xlfn.UNIQUE(_xlfn._xlws.FILTER('Helper Results'!A:A,('Helper Results'!D:D=$B8)*('Helper Results'!A:A<>""))), ""),_xlpm.counts,IF(_xlpm.dates="", 0, COUNTIFS('Helper Results'!D:D, $B8, 'Helper Results'!A:A, _xlpm.dates, 'Helper Results'!E:E, "Win")),SUMPRODUCT(--(_xlpm.counts=3))+2*SUMPRODUCT(--(_xlpm.counts>=4)))} -> 2 | I8: =G8+H8 -> 31 | J8: =RANK(I8,$I$2:$I$31) -> 6
A9: 8 | B9: Natalya | C9: =COUNTIF('Helper Results'!D:D,B9) -> 13 | D9: =COUNTIFS('Helper Results'!D:D,B9,'Helper Results'!E:E,"Win") -> 7 | E9: =COUNTIFS('Helper Results'!D:D,B9,'Helper Results'!E:E,"Draw") -> 0 | F9: =COUNTIFS('Helper Results'!D:D,B9,'Helper Results'!E:E,"Loss") -> 6 | G9: =SUMIF('Helper Results'!D:D,B9,'Helper Results'!F:F) -> 27 | H9: {=_xlfn.LET(_xlpm.dates,IFERROR(_xlfn.UNIQUE(_xlfn._xlws.FILTER('Helper Results'!A:A,('Helper Results'!D:D=$B9)*('Helper Results'!A:A<>""))), ""),_xlpm.counts,IF(_xlpm.dates="", 0, COUNTIFS('Helper Results'!D:D, $B9, 'Helper Results'!A:A, _xlpm.dates, 'Helper Results'!E:E, "Win")),SUMPRODUCT(--(_xlpm.counts=3))+2*SUMPRODUCT(--(_xlpm.counts>=4)))} -> 1 | I9: =G9+H9 -> 28 | J9: =RANK(I9,$I$2:$I$31) -> 8
A10: 9 | B10: Vivek | C10: =COUNTIF('Helper Results'!D:D,B10) -> 10 | D10: =COUNTIFS('Helper Results'!D:D,B10,'Helper Results'!E:E,"Win") -> 7 | E10: =COUNTIFS('Helper Results'!D:D,B10,'Helper Results'!E:E,"Draw") -> 1 | F10: =COUNTIFS('Helper Results'!D:D,B10,'Helper Results'!E:E,"Loss") -> 2 | G10: =SUMIF('Helper Results'!D:D,B10,'Helper Results'!F:F) -> 25 | H10: {=_xlfn.LET(_xlpm.dates,IFERROR(_xlfn.UNIQUE(_xlfn._xlws.FILTER('Helper Results'!A:A,('Helper Results'!D:D=$B10)*('Helper Results'!A:A<>""))), ""),_xlpm.counts,IF(_xlpm.dates="", 0, COUNTIFS('Helper Results'!D:D, $B10, 'Helper Results'!A:A, _xlpm.dates, 'Helper Results'!E:E, "Win")),SUMPRODUCT(--(_xlpm.counts=3))+2*SUMPRODUCT(--(_xlpm.counts>=4)))} -> 2 | I10: =G10+H10 -> 27 | J10: =RANK(I10,$I$2:$I$31) -> 9
A11: 10 | B11: Sharuk | C11: =COUNTIF('Helper Results'!D:D,B11) -> 12 | D11: =COUNTIFS('Helper Results'!D:D,B11,'Helper Results'!E:E,"Win") -> 6 | E11: =COUNTIFS('Helper Results'!D:D,B11,'Helper Results'!E:E,"Draw") -> 0 | F11: =COUNTIFS('Helper Results'!D:D,B11,'Helper Results'!E:E,"Loss") -> 6 | G11: =SUMIF('Helper Results'!D:D,B11,'Helper Results'!F:F) -> 24 | H11: {=_xlfn.LET(_xlpm.dates,IFERROR(_xlfn.UNIQUE(_xlfn._xlws.FILTER('Helper Results'!A:A,('Helper Results'!D:D=$B11)*('Helper Results'!A:A<>""))), ""),_xlpm.counts,IF(_xlpm.dates="", 0, COUNTIFS('Helper Results'!D:D, $B11, 'Helper Results'!A:A, _xlpm.dates, 'Helper Results'!E:E, "Win")),SUMPRODUCT(--(_xlpm.counts=3))+2*SUMPRODUCT(--(_xlpm.counts>=4)))} -> 1 | I11: =G11+H11 -> 25 | J11: =RANK(I11,$I$2:$I$31) -> 10
A12: 11 | B12: Amit | C12: =COUNTIF('Helper Results'!D:D,B12) -> 14 | D12: =COUNTIFS('Helper Results'!D:D,B12,'Helper Results'!E:E,"Win") -> 5 | E12: =COUNTIFS('Helper Results'!D:D,B12,'Helper Results'!E:E,"Draw") -> 0 | F12: =COUNTIFS('Helper Results'!D:D,B12,'Helper Results'!E:E,"Loss") -> 9 | G12: =SUMIF('Helper Results'!D:D,B12,'Helper Results'!F:F) -> 24 | H12: {=_xlfn.LET(_xlpm.dates,IFERROR(_xlfn.UNIQUE(_xlfn._xlws.FILTER('Helper Results'!A:A,('Helper Results'!D:D=$B12)*('Helper Results'!A:A<>""))), ""),_xlpm.counts,IF(_xlpm.dates="", 0, COUNTIFS('Helper Results'!D:D, $B12, 'Helper Results'!A:A, _xlpm.dates, 'Helper Results'!E:E, "Win")),SUMPRODUCT(--(_xlpm.counts=3))+2*SUMPRODUCT(--(_xlpm.counts>=4)))} -> 1 | I12: =G12+H12 -> 25 | J12: =RANK(I12,$I$2:$I$31) -> 10
A13: 12 | B13: Own | C13: =COUNTIF('Helper Results'!D:D,B13) -> 12 | D13: =COUNTIFS('Helper Results'!D:D,B13,'Helper Results'!E:E,"Win") -> 5 | E13: =COUNTIFS('Helper Results'!D:D,B13,'Helper Results'!E:E,"Draw") -> 1 | F13: =COUNTIFS('Helper Results'!D:D,B13,'Helper Results'!E:E,"Loss") -> 6 | G13: =SUMIF('Helper Results'!D:D,B13,'Helper Results'!F:F) -> 23 | H13: {=_xlfn.LET(_xlpm.dates,IFERROR(_xlfn.UNIQUE(_xlfn._xlws.FILTER('Helper Results'!A:A,('Helper Results'!D:D=$B13)*('Helper Results'!A:A<>""))), ""),_xlpm.counts,IF(_xlpm.dates="", 0, COUNTIFS('Helper Results'!D:D, $B13, 'Helper Results'!A:A, _xlpm.dates, 'Helper Results'!E:E, "Win")),SUMPRODUCT(--(_xlpm.counts=3))+2*SUMPRODUCT(--(_xlpm.counts>=4)))} -> 1 | I13: =G13+H13 -> 24 | J13: =RANK(I13,$I$2:$I$31) -> 12
... A27: 26 | B27: Reza | C27: =COUNTIF('Helper Results'!D:D,B27) -> 2 | D27: =COUNTIFS('Helper Results'!D:D,B27,'Helper Results'!E:E,"Win") -> 0 | E27: =COUNTIFS('Helper Results'!D:D,B27,'Helper Results'!E:E,"Draw") -> 0 | F27: =COUNTIFS('Helper Results'!D:D,B27,'Helper Results'!E:E,"Loss") -> 2 | G27: =SUMIF('Helper Results'!D:D,B27,'Helper Results'!F:F) -> 2 | H27: {=_xlfn.LET(_xlpm.dates,IFERROR(_xlfn.UNIQUE(_xlfn._xlws.FILTER('Helper Results'!A:A,('Helper Results'!D:D=$B27)*('Helper Results'!A:A<>""))), ""),_xlpm.counts,IF(_xlpm.dates="", 0, COUNTIFS('Helper Results'!D:D, $B27, 'Helper Results'!A:A, _xlpm.dates, 'Helper Results'!E:E, "Win")),SUMPRODUCT(--(_xlpm.counts=3))+2*SUMPRODUCT(--(_xlpm.counts>=4)))} -> 0 | I27: =G27+H27 -> 2 | J27: =RANK(I27,$I$2:$I$31) -> 26
